Traceback (most recent call last):
  File "C:\Program Files\Python38\lib\site-packages\transformers\configuration_utils.py", line 550, in get_config_dict
    resolved_config_file = cached_path(
  File "C:\Program Files\Python38\lib\site-packages\transformers\file_utils.py", line 1491, in cached_path
    output_path = get_from_cache(
  File "C:\Program Files\Python38\lib\site-packages\transformers\file_utils.py", line 1663, in get_from_cache
    r.raise_for_status()
  File "C:\Users\fostroll\AppData\Roaming\Python\Python38\site-packages\requests\models.py", line 941, in raise_for_status
    raise HTTPError(http_error_msg, response=self)
requests.exceptions.HTTPError: 404 Client Error: Not Found for url: https://huggingface.co/model%5Cmodel0%5Cmodel_emb/resolve/main/config.json

During handling of the above exception, another exception occurred:

Traceback (most recent call last):
  File "server/main.py", line 33, in reload_model
    model_load(schemata.config.model_name,
  File "C:\prj-git\_mine\modelsrv0\server\model\spec.py", line 43, in model_load
    model = Model.load(path)
  File "C:\prj-git\_mine\modelsrv0\server\model\model.py", line 65, in load
    emb, tokenizer, head = cls._load(path)
  File "C:\prj-git\_mine\modelsrv0\server\model\model.py", line 59, in _load
    emb, tokenizer = cls._load_bert(os.path.join(path, cls._model_emb_dn))
  File "C:\prj-git\_mine\modelsrv0\server\model\model.py", line 50, in _load_bert
    tokenizer = AutoTokenizer.from_pretrained(path, do_lower_case=False)
  File "C:\Program Files\Python38\lib\site-packages\transformers\models\auto\tokenization_auto.py", line 470, in from_pretrained
    config = AutoConfig.from_pretrained(pretrained_model_name_or_path, **kwargs)
  File "C:\Program Files\Python38\lib\site-packages\transformers\models\auto\configuration_auto.py", line 558, in from_pretrained
    config_dict, _ = PretrainedConfig.get_config_dict(pretrained_model_name_or_path, **kwargs)
  File "C:\Program Files\Python38\lib\site-packages\transformers\configuration_utils.py", line 575, in get_config_dict
    raise EnvironmentError(msg)
OSError: Can't load config for 'model\model0\model_emb'. Make sure that:

- 'model\model0\model_emb' is a correct model identifier listed on 'https://huggingface.co/models'
  (make sure 'model\model0\model_emb' is not a path to a local directory with something else, in that case)

- or 'model\model0\model_emb' is the correct path to a directory containing a config.json file



